##　解答

### f1

- 予想: A, B, Cの順で間髪おかず出力される
- 結果: A, B, Cが時間間隔を置いて出力される
- 理由: awaitで記述すると、wait3() ⇒ log(A) ⇒ wait2() ⇒ log(B) ⇒ wait() ⇒ log(A)の順で実行されるため。

### f2, f3

- 予想: 共にXが出力される
- 結果: f2のみXが出力される
- 理由: async関数の戻り値はPromiseであり、このPromiseのチェーン上にはcatchが存在しないから。

### f4

- 予想: Xのみキャッチされる
- 結果: どちらもキャッチされずに、ErrYが発生する。
- 理由: まずp1でwait2().then()が先に実行される。そののち、p2の中身wait1().thenが実行される。await p1によりp1の完了を待とうとするが、その前すでに走り出してしまったp2のwait1()が完了してしまう。await p2はまだ実行されていないので、p2のエラーをキャッチするモノはp2のPromiseチェーン上には存在しないため、これがリリースされるから。
